<?xml version="1.0"?>
<robot name="romi">
  
  <!-- ========================================== -->
  <!-- BASE LINK (CHASSIS) -->
  <!-- ========================================== -->
  <link name="base_link">
    <visual>
      <!-- Match kinematics/origin from romi.urdf "-0.163 -0.0745 -0.036 -->
      <origin xyz="0.05 +0.155 -0.06" rpy="1.5708 0 -1.5708"/>
      <geometry>
        <!-- STL mesh path relative to this URDF file -->
        <mesh filename="model://romi_gazebo/meshes/visual/chasis.stl" scale="0.001 0.001 0.001"/>
      </geometry>
      <material name="blue">
        <color rgba="0.2 0.2 0.8 1.0"/>
      </material>
    </visual>
    <collision>
      <origin xyz="0 0 0.02" rpy="0 0 0"/>
      <geometry>
        <box size="0.16 0.14 0.04"/>
      </geometry>
    </collision>
    <inertial>
      <origin xyz="0 0 0.02" rpy="0 0 0"/>
      <mass value="0.8"/>
      <inertia ixx="0.00146" ixy="0.0" ixz="0.0" 
               iyy="0.00189" iyz="0.0" 
               izz="0.00288"/>
    </inertial>
  </link>

  <!-- ========================================== -->
  <!-- LEFT WHEEL -->
  <!-- ========================================== -->
  <link name="left_wheel">
    <visual>
      <!-- Match left_wheel link origin from romi.urdf -->
      <origin xyz="0 0 0" rpy="0 1.5708 1.5708"/>
      <geometry>
        <!-- STL mesh path relative to this URDF file -->
        <mesh filename="model://romi_gazebo/meshes/visual/wheel.stl" scale="0.001 0.001 0.001"/>
      </geometry>
      <material name="black">
        <color rgba="0.1 0.1 0.1 1.0"/>
      </material>
    </visual>
    <collision>
      <origin xyz="0 0 0" rpy="0 0 0"/>
      <geometry>
        <cylinder radius="0.035" length="0.015"/>
      </geometry>
    </collision>
    <inertial>
      <origin xyz="0 0 0" rpy="0 0 0"/>
      <mass value="0.05"/>
      <inertia ixx="3.125e-05" ixy="0.0" ixz="0.0"
               iyy="3.125e-05" iyz="0.0"
               izz="6.125e-05"/>
    </inertial>
  </link>

  <joint name="left_wheel_joint" type="continuous">
    <parent link="base_link"/>
    <child link="left_wheel"/>
    <!-- Copy joint transform from romi.urdf -->
    <origin xyz="0 -0.07 0.035" rpy="1.5708 0 0"/>
    <axis xyz="0 0 1"/>
    <limit effort="1.0" velocity="10.0"/>
  </joint>

  <!-- ========================================== -->
  <!-- RIGHT WHEEL -->
  <!-- ========================================== -->
  <link name="right_wheel">
    <visual>
      <!-- Match right_wheel link origin from romi.urdf -->
      <!-- Flipped 180 degrees around Z-axis (rotating axis) -->
      <origin xyz="0 0 0" rpy="0 1.5708 4.71239"/>
      <geometry>
        <!-- STL mesh path relative to this URDF file -->
        <mesh filename="model://romi_gazebo/meshes/visual/wheel.stl" scale="0.001 0.001 0.001"/>
      </geometry>
      <material name="black">
        <color rgba="0.1 0.1 0.1 1.0"/>
      </material>
    </visual>
    <collision>
      <origin xyz="0 0 0" rpy="0 0 0"/>
      <geometry>
        <cylinder radius="0.035" length="0.015"/>
      </geometry>
    </collision>
    <inertial>
      <origin xyz="0 0 0" rpy="0 0 0"/>
      <mass value="0.05"/>
      <inertia ixx="3.125e-05" ixy="0.0" ixz="0.0"
               iyy="3.125e-05" iyz="0.0"
               izz="6.125e-05"/>
    </inertial>
  </link>

  <joint name="right_wheel_joint" type="continuous">
    <parent link="base_link"/>
    <child link="right_wheel"/>
    <!-- Copy joint transform from romi.urdf -->
    <origin xyz="0.0 0.07 0.035" rpy="1.5708 0 0"/>
    <axis xyz="0 0 1"/>
    <limit effort="1.0" velocity="10.0"/>
  </joint>

  <!-- ========================================== -->
  <!-- FRONT CASTER BALL -->
  <!-- ========================================== -->
  <link name="front_caster_ball">
    <visual>
      <origin xyz="0 0 0" rpy="0 0 0"/>
      <geometry>
        <!-- Simple primitive visual (no STL mesh file yet) -->
        <sphere radius="0.0127"/>
      </geometry>
      <material name="gray">
        <color rgba="0.5 0.5 0.5 1.0"/>
      </material>
    </visual>
    <collision>
      <origin xyz="0 0 0" rpy="0 0 0"/>
      <geometry>
        <sphere radius="0.0127"/>
      </geometry>
    </collision>
    <inertial>
      <origin xyz="0 0 0" rpy="0 0 0"/>
      <mass value="0.0135"/>
      <inertia ixx="4.34e-07" ixy="0.0" ixz="0.0"
               iyy="4.34e-07" iyz="0.0"
               izz="4.34e-07"/>
    </inertial>
  </link>

  <joint name="front_caster_ball_joint" type="fixed">
    <parent link="base_link"/>
    <child link="front_caster_ball"/>
    <origin xyz="0.065 0 0.0127" rpy="0 0 0"/>
  </joint>

  <!-- ========================================== -->
  <!-- REAR CASTER BALL -->
  <!-- ========================================== -->
  <link name="rear_caster_ball">
    <visual>
      <origin xyz="0 0 0" rpy="0 0 0"/>
      <geometry>
        <!-- Simple primitive visual (no STL mesh file yet) -->
        <sphere radius="0.0127"/>
      </geometry>
      <material name="white">
        <color rgba="0.9 0.9 0.9 1.0"/>
      </material>
    </visual>
    <collision>
      <origin xyz="0 0 0" rpy="0 0 0"/>
      <geometry>
        <sphere radius="0.0127"/>
      </geometry>
    </collision>
    <inertial>
      <origin xyz="0 0 0" rpy="0 0 0"/>
      <mass value="0.0135"/>
      <inertia ixx="4.34e-07" ixy="0.0" ixz="0.0"
               iyy="4.34e-07" iyz="0.0"
               izz="4.34e-07"/>
    </inertial>
  </link>

  <joint name="rear_caster_ball_joint" type="fixed">
    <parent link="base_link"/>
    <child link="rear_caster_ball"/>
    <origin xyz="-0.042 0 0.0127" rpy="0 0 0"/>
  </joint>

  <!-- ========================================== -->
  <!-- SENSOR MOUNT (OPTIONAL) -->
  <!-- ========================================== -->
  <link name="sensor_mount">
    <!-- Visual removed to hide the green box -->
    <inertial>
      <origin xyz="0 0 0.015" rpy="0 0 0"/>
      <mass value="0.05"/>
      <inertia ixx="3.667e-05" ixy="0.0" ixz="0.0"
               iyy="3.667e-05" iyz="0.0"
               izz="6.667e-05"/>
    </inertial>
  </link>

  <joint name="sensor_mount_joint" type="fixed">
    <parent link="base_link"/>
    <child link="sensor_mount"/>
    <origin xyz="0.0 0 0.04" rpy="0 0 0"/>
  </joint>

  <!-- ========================================== -->
  <!-- IMU LINK (OPTIONAL SENSOR) -->
  <!-- ========================================== -->
  <link name="imu_link">
    <visual>
      <!-- Rotate to lay the board flat (horizontal) - 90 degrees around X axis -->
      <!-- Adjust position to center the board on the sensor mount -->
      <origin xyz="0.095 0.102 -0.125" rpy="1.5708 0 -1.5708"/>
      <geometry>
        <!-- STL mesh path relative to this URDF file -->
        <mesh filename="model://romi_gazebo/meshes/visual/control_board.stl" scale="0.001 0.001 0.001"/>
      </geometry>
          <material name="gray">
            <color rgba="0.7 0.7 0.7 1.0"/>
          </material>
    </visual>
    <!-- Collision matching visual to avoid default box -->
    <collision>
      <origin xyz="0.095 0.105 -0.125" rpy="1.5708 0 -1.5708"/>
      <geometry>
        <mesh filename="model://romi_gazebo/meshes/visual/control_board.stl" scale="0.001 0.001 0.001"/>
      </geometry>
    </collision>
    <inertial>
      <origin xyz="0 0 0" rpy="0 0 0"/>
      <mass value="0.005"/>
      <inertia ixx="2.292e-07" ixy="0.0" ixz="0.0"
               iyy="2.292e-07" iyz="0.0"
               izz="4.167e-07"/>
    </inertial>
  </link>

  <joint name="imu_joint" type="fixed">
    <parent link="sensor_mount"/>
    <child link="imu_link"/>
    <origin xyz="0 0 0.03" rpy="0 0 0"/>
  </joint>

  <!-- ========================================== -->
  <!-- RASPBERRY PI CAMERA MODULE 2 -->
  <!-- ========================================== -->
  <link name="camera_link">
    <visual>
      <!-- Position box far behind camera (negative X = behind, since camera looks forward along +X) -->
      <!-- Box center at -50mm, with 9mm thickness, front edge at -45.5mm, well behind 12.5mm near plane -->
      <origin xyz="0 0 0" rpy="0 0 0"/>
      <geometry>
        <!-- Raspberry Pi Camera Module 2: ~25mm x 24mm x 9mm -->
        <box size="0.009 0.025 0.024"/>
      </geometry>
      <material name="brown">
        <color rgba="0.6 0.4 0.2 1.0"/>
      </material>
    </visual>
    <inertial>
      <origin xyz="0 0 0" rpy="0 0 0"/>
      <mass value="0.003"/>
      <inertia ixx="1.8e-07" ixy="0.0" ixz="0.0"
               iyy="1.8e-07" iyz="0.0"
               izz="3.6e-07"/>
    </inertial>
  </link>

  <joint name="camera_joint" type="fixed">
    <parent link="sensor_mount"/>
    <child link="camera_link"/>
    <!-- Position camera on sensor mount, facing forward -->
    <origin xyz="0.05 0 0.03" rpy="0 0 0"/>
  </joint>

  <!-- Gazebo Camera Plugin -->
  <gazebo reference="camera_link">
    <sensor type="camera" name="camera">
      <update_rate>30</update_rate>
      <camera>
        <horizontal_fov>1.047</horizontal_fov>
        <image>
          <width>3280</width>
          <height>2464</height>
          <format>R8G8B8</format>
        </image>
        <clip>
          <near>0.05</near>
          <far>100</far>
        </clip>
      </camera>
      <plugin name="camera_controller" filename="libgazebo_ros_camera.so">
        <ros>
          <namespace>/romi</namespace>
          <remapping>image_raw:=camera/image_raw</remapping>
          <remapping>camera_info:=camera/camera_info</remapping>
        </ros>
        <camera_name>camera</camera_name>
        <frame_name>camera_link</frame_name>
        <hack_baseline>0.07</hack_baseline>
        <min_depth>0.05</min_depth>
        <max_depth>100.0</max_depth>
      </plugin>
    </sensor>
  </gazebo>

  <!-- ROS2 Control Hardware Interface -->
  <ros2_control name="GazeboSimSystem" type="system">
    <hardware>
      <plugin>gz_ros2_control/GazeboSimSystem</plugin>
    </hardware>
    <joint name="left_wheel_joint">
      <command_interface name="velocity">
        <param name="min">-10</param>
        <param name="max">10</param>
      </command_interface>
      <state_interface name="position"/>
      <state_interface name="velocity"/>
    </joint>
    <joint name="right_wheel_joint">
      <command_interface name="velocity">
        <param name="min">-10</param>
        <param name="max">10</param>
      </command_interface>
      <state_interface name="position"/>
      <state_interface name="velocity"/>
    </joint>
  </ros2_control>

</robot>

